# 22 Mon

## \[HEAD FIRST PYTHON\] 11강 예외 처리 <a id="sql"></a>

### 발생할 수 있는 문제

* 데이터 베이스 연결 실패
* 웹 공격
  * SQL 인젝션 : 백엔드 데이터베이스를 노린 공격
  * 사이트 스크티립팅 : 웹사이트를 노린 공격
* 입출력의 처리 시간
* 함수 호출의 실패
  * builtins.RuntimeError

코드나 로직이 잘못되면 에러를 발생시키게 된다. 대부분의 에러는 인터프리터에서 내장된 예외로 처리한다. 모든 내장 예외 목록은 https://docs.python.org/3/library/exceptions.html 에서 확인할 수 있다.

에러를 잡는 것에서 그치는 것이 아니라 에러가 발생했을 때의 예외를 처리하도록 개선하는 코드를 짜야된다.

```python
try:
    with open("file.txt") as f:
        data = f.read()
    print(data)
except FileNotFoundError:
    print("File is missing")
```

이 때 다양한 문제가 발생할 수 있다. 모든 에러는 Exception을 상속받는다.

![https://dojang.io/mod/page/view.php?id=2398](../../.gitbook/assets/image%20%28616%29.png)

* FileNotFoundError
* PermissionError
* NameError
* EOFError
* BufferError
* OSError
* MemoryError
* and so on

다양한 문제를 개별적으로 처리하기에는 한계가 있다. 모든 런타임 에러를 잡아 처리할 수 있는 예외 처리 스위트가 존재한다.

```python
try:
    with open("file.txt") as f:
        data = f.read()
    print(data)
except FileNotFoundError:
    print("File is missing")
except:
    print("Something wrong")
```

이 때의 문제점도 있다. 어떤 오류가 났는지 자세히 알 수 없기 때문이다. 이 때는 `sys` 로 예외 정보를 얻을 수 있다.

* `sys.exc_info()` 로 현재 처리 중인 예외의 정보를 얻을 수 있다.
  * 예외의 유형, 예외 값, 역추적 객체의 3가지 값을 갖는 튜플을 반환한다.
  * 예외가 없으면 `(None, None, None)` 을 반환한다.

```python
try:
    1 / 0
except:
    err = sys.exc_info()
    for e in err:
        print(e)

>>> <class 'ZeroDivisionError'>
>>> division by zero
>>> traceback object at 0x105b22188>
```

모든 예외는 Exception을 상속받기 때문에 다음과 같이 예외를 처리할 수 있다.

```python
try:
    with open("file.txt") as f:
        data = f.read()
    print(data)
except FileNotFoundError:
    print("File is missing")
except Exception as err:
    print("Something wrong : ", str(err))
```

이 때, 다음과 같이 강하게 결합된 코드를 지양해야 한다. python backend 코드와 mysql backend database가 강하게 결합되었기 때문이다. 이는 후에 MySQL을 PostgreSQL로 바꿔야 할 때 곤란한 점이 될 수 있다.

```python
except mysql.connector.errors.InterfaceError as err:
```

커스텀 예외를 만들 수도 있다. 커스텀 예외 클래스를 정의하고 Exception 클래스를 상속 받도록 한다. 이 때, `raise` 키워드로 예외를 발생시킬 수 있다.

```python
class ConnectionError(Exception):
    pass
    
try:
    raise ConnectionError("Butter!")
except ConnectionError as err:
    print(str(err))

>>> "Butter!"
```

* 이 때 `ConnectionError` 내부를 pass로 정의했지만 실제로는 Exception의 모든 기능을 가지고있다. 그래서 아무런 문제가 없이 실행되는 모습.

